Workbook

Sheet Dashboard
B2: Forge: feature tracker
B3: Counts come from the Features sheet and update when you change Status or add rows.
B5: Total | C5: Done | D5: Partial | E5: Not started | F5: % done
B6: =COUNTA(Features!$A$2:$A$500) | C6: =COUNTIF(Features!$D$2:$D$500,"Done") | D6: =COUNTIF(Features!$D$2:$D$500,"Partial") | E6: =COUNTIF(Features!$D$2:$D$500,"Not started") | F6: =IF(B6=0,0,C6/B6)
B8: By area
B9: Area | C9: Done | D9: Partial | E9: Not started | F9: Total | G9: % done
B10: Editing | C10: =COUNTIFS(Features!$B$2:$B$500,$B10,Features!$D$2:$D$500,"Done") | D10: =COUNTIFS(Features!$B$2:$B$500,$B10,Features!$D$2:$D$500,"Partial") | E10: =COUNTIFS(Features!$B$2:$B$500,$B10,Features!$D$2:$D$500,"Not started") | F10: =SUM(C10:E10) | G10: =IF(F10=0,0,C10/F10)
B11: Navigation | C11: =COUNTIFS(Features!$B$2:$B$500,$B11,Features!$D$2:$D$500,"Done") | D11: =COUNTIFS(Features!$B$2:$B$500,$B11,Features!$D$2:$D$500,"Partial") | E11: =COUNTIFS(Features!$B$2:$B$500,$B11,Features!$D$2:$D$500,"Not started") | F11: =SUM(C11:E11) | G11: =IF(F11=0,0,C11/F11)
B12: Workbench | C12: =COUNTIFS(Features!$B$2:$B$500,$B12,Features!$D$2:$D$500,"Done") | D12: =COUNTIFS(Features!$B$2:$B$500,$B12,Features!$D$2:$D$500,"Partial") | E12: =COUNTIFS(Features!$B$2:$B$500,$B12,Features!$D$2:$D$500,"Not started") | F12: =SUM(C12:E12) | G12: =IF(F12=0,0,C12/F12)
B13: Terminal | C13: =COUNTIFS(Features!$B$2:$B$500,$B13,Features!$D$2:$D$500,"Done") | D13: =COUNTIFS(Features!$B$2:$B$500,$B13,Features!$D$2:$D$500,"Partial") | E13: =COUNTIFS(Features!$B$2:$B$500,$B13,Features!$D$2:$D$500,"Not started") | F13: =SUM(C13:E13) | G13: =IF(F13=0,0,C13/F13)
B14: Language servers | C14: =COUNTIFS(Features!$B$2:$B$500,$B14,Features!$D$2:$D$500,"Done") | D14: =COUNTIFS(Features!$B$2:$B$500,$B14,Features!$D$2:$D$500,"Partial") | E14: =COUNTIFS(Features!$B$2:$B$500,$B14,Features!$D$2:$D$500,"Not started") | F14: =SUM(C14:E14) | G14: =IF(F14=0,0,C14/F14)
B15: Source control | C15: =COUNTIFS(Features!$B$2:$B$500,$B15,Features!$D$2:$D$500,"Done") | D15: =COUNTIFS(Features!$B$2:$B$500,$B15,Features!$D$2:$D$500,"Partial") | E15: =COUNTIFS(Features!$B$2:$B$500,$B15,Features!$D$2:$D$500,"Not started") | F15: =SUM(C15:E15) | G15: =IF(F15=0,0,C15/F15)
B16: Debugging | C16: =COUNTIFS(Features!$B$2:$B$500,$B16,Features!$D$2:$D$500,"Done") | D16: =COUNTIFS(Features!$B$2:$B$500,$B16,Features!$D$2:$D$500,"Partial") | E16: =COUNTIFS(Features!$B$2:$B$500,$B16,Features!$D$2:$D$500,"Not started") | F16: =SUM(C16:E16) | G16: =IF(F16=0,0,C16/F16)
B17: Extensions | C17: =COUNTIFS(Features!$B$2:$B$500,$B17,Features!$D$2:$D$500,"Done") | D17: =COUNTIFS(Features!$B$2:$B$500,$B17,Features!$D$2:$D$500,"Partial") | E17: =COUNTIFS(Features!$B$2:$B$500,$B17,Features!$D$2:$D$500,"Not started") | F17: =SUM(C17:E17) | G17: =IF(F17=0,0,C17/F17)
B18: Text and files | C18: =COUNTIFS(Features!$B$2:$B$500,$B18,Features!$D$2:$D$500,"Done") | D18: =COUNTIFS(Features!$B$2:$B$500,$B18,Features!$D$2:$D$500,"Partial") | E18: =COUNTIFS(Features!$B$2:$B$500,$B18,Features!$D$2:$D$500,"Not started") | F18: =SUM(C18:E18) | G18: =IF(F18=0,0,C18/F18)
B19: Highlighting | C19: =COUNTIFS(Features!$B$2:$B$500,$B19,Features!$D$2:$D$500,"Done") | D19: =COUNTIFS(Features!$B$2:$B$500,$B19,Features!$D$2:$D$500,"Partial") | E19: =COUNTIFS(Features!$B$2:$B$500,$B19,Features!$D$2:$D$500,"Not started") | F19: =SUM(C19:E19) | G19: =IF(F19=0,0,C19/F19)
B20: Packaging | C20: =COUNTIFS(Features!$B$2:$B$500,$B20,Features!$D$2:$D$500,"Done") | D20: =COUNTIFS(Features!$B$2:$B$500,$B20,Features!$D$2:$D$500,"Partial") | E20: =COUNTIFS(Features!$B$2:$B$500,$B20,Features!$D$2:$D$500,"Not started") | F20: =SUM(C20:E20) | G20: =IF(F20=0,0,C20/F20)
B21: Total | C21: =SUM(C10:C20) | D21: =SUM(D10:D20) | E21: =SUM(E10:E20) | F21: =SUM(F10:F20) | G21: =IF(F21=0,0,C21/F21)
B23: Open items by priority
B24: Priority | C24: Partial | D24: Not started | E24: Open
B25: High | C25: =COUNTIFS(Features!$E$2:$E$500,$B25,Features!$D$2:$D$500,"Partial") | D25: =COUNTIFS(Features!$E$2:$E$500,$B25,Features!$D$2:$D$500,"Not started") | E25: =C25+D25
B26: Medium | C26: =COUNTIFS(Features!$E$2:$E$500,$B26,Features!$D$2:$D$500,"Partial") | D26: =COUNTIFS(Features!$E$2:$E$500,$B26,Features!$D$2:$D$500,"Not started") | E26: =C26+D26
B27: Low | C27: =COUNTIFS(Features!$E$2:$E$500,$B27,Features!$D$2:$D$500,"Partial") | D27: =COUNTIFS(Features!$E$2:$E$500,$B27,Features!$D$2:$D$500,"Not started") | E27: =C27+D27
B29: Done but not run in the app | E29: =COUNTIFS(Features!$F$2:$F$500,"Tests")+COUNTIFS(Features!$F$2:$F$500,"Not verified")
B30: (Verified = Tests or Not verified)

Sheet Features
A1: ID | B1: Area | C1: Feature | D1: Status | E1: Priority | F1: Verified | G1: Notes | H1: Owner | I1: Updated
A2: F-001 | B2: Editing | C2: Multi-cursor editing | D2: Done | F2: App | G2: Ctrl+D / Ctrl+Alt+Up/Down / Ctrl+Shift+L | I2: 46325
A3: F-002 | B3: Editing | C3: Find and replace in file | D3: Done | F3: App | I3: 46325
A4: F-003 | B4: Editing | C4: Find and Replace in Files | D4: Done | F4: App | I4: 46325
A5: F-004 | B5: Editing | C5: Code folding | D5: Done | F5: App | I5: 46325
A6: F-005 | B6: Editing | C6: Snippets | D6: Done | F6: App | G6: Prefix + Tab, popup, tab stops, mirrors, choices, variables, transforms; see F-104 to F-110 | I6: 46325
A7: F-006 | B7: Editing | C7: Format Document | D7: Done | F7: App | G7: Needs a language server; per-language tab size is used | I7: 46325
A8: F-007 | B8: Editing | C8: Format Selection | D8: Partial | E8: Medium | F8: Not verified | G8: Builds and sends rangeFormatting; never tried against a running language server | I8: 46325
A9: F-008 | B9: Editing | C9: Organize Imports | D9: Partial | E9: Medium | F9: Not verified | G9: Builds and sends source.organizeImports; never tried against a running language server | I9: 46325
A10: F-009 | B10: Editing | C10: Auto Save (afterDelay / onFocusChange) | D10: Done | F10: App | G10: Saves only the file in front (afterDelay); format on save is not run by it | I10: 46325
A11: F-010 | B11: Editing | C11: Per-language settings ([lang] blocks) | D11: Partial | E11: Low | F11: Tests | G11: Only editor.tabSize / insertSpaces / formatOnSave are read; other settings are global | I11: 46325
A12: F-011 | B12: Editing | C12: Word wrap and minimap | D12: Done | F12: App | I12: 46325
A13: F-012 | B13: Editing | C13: Emmet (HTML, JSX, CSS; Tab to expand) | D13: Done | F13: App | G13: A practical subset: no filters, no lorem, fewer CSS abbreviations | I13: 46325
A14: F-013 | B14: Editing | C14: Spell checking | D14: Not started | E14: Low | I14: 46325
A15: F-014 | B15: Editing | C15: Sticky scroll | D15: Done | F15: App | G15: From folding regions; hidden with word wrap on | I15: 46325
A16: F-015 | B16: Editing | C16: Linked editing (auto rename paired tags) | D16: Done | F16: App | G16: HTML, XML, JSX; not for other linked ranges a server might offer | I16: 46325
A17: F-016 | B17: Editing | C17: Drag and drop of text | D17: Not started | E17: Medium | I17: 46325
A18: F-017 | B18: Editing | C18: Bookmarks | D18: Not started | E18: Low | I18: 46325
A19: F-018 | B19: Editing | C19: Snippets in the completion popup | D19: Done | F19: App | G19: Language-server completions are still plain text (F-110) | I19: 46325
A20: F-019 | B20: Navigation | C20: Quick Open and Command Palette | D20: Done | F20: App | I20: 46325
A21: F-020 | B21: Navigation | C21: Go to Symbol / Line / Bracket | D21: Done | F21: App | I21: 46325
A22: F-021 | B22: Navigation | C22: Go Back / Go Forward (Alt+Left/Right) | D22: Done | F22: App | I22: 46325
A23: F-022 | B23: Navigation | C23: Reopen Closed Editor (Ctrl+Shift+T) | D23: Done | F23: App | I23: 46325
A24: F-023 | B24: Navigation | C24: Open Recent (Ctrl+R) | D24: Done | F24: App | I24: 46325
A25: F-024 | B25: Navigation | C25: Zen mode | D25: Done | F25: App | G25: Hides side bar and panel only | I25: 46325
A26: F-025 | B26: Navigation | C26: Compare two files | D26: Done | F26: App | G26: Uses git diff --no-index; git must be installed | I26: 46325
A27: F-026 | B27: Navigation | C27: Outline (symbol picker) | D27: Partial | E27: Medium | F27: App | G27: Picker only; no permanent tree view | I27: 46325
A28: F-027 | B28: Navigation | C28: Workspace symbol search (Ctrl+T) | D28: Not started | E28: Medium | G28: Needs workspace/symbol request and an overlay | I28: 46325
A29: F-028 | B29: Navigation | C29: Peek Definition / References | D29: Not started | E29: Medium | I29: 46325
A30: F-029 | B30: Navigation | C30: Call Hierarchy and Type Hierarchy | D30: Not started | E30: Low | I30: 46325
A31: F-030 | B31: Navigation | C31: Search Editor | D31: Not started | E31: Low | I31: 46325
A32: F-031 | B32: Workbench | C32: Menu bar (File Edit Selection View Go Run Terminal Help) | D32: Done | F32: App | G32: Mouse only | I32: 46325
A33: F-032 | B33: Workbench | C33: Menu bar access keys (Alt+F etc.) | D33: Not started | E33: Low | I33: 46325
A34: F-033 | B34: Workbench | C34: Explorer toolbar (New File / New Folder / Refresh / Collapse) | D34: Done | F34: App | G34: Refresh and Collapse: Collapse unit-tested | I34: 46325
A35: F-034 | B35: Workbench | C35: Explorer right-click menu for folders | D35: Done | F35: App | I35: 46325
A36: F-035 | B36: Workbench | C36: Explorer right-click menu for files | D36: Done | F36: App | I36: 46325
A37: F-036 | B37: Workbench | C37: Explorer right-click menu on empty space | D37: Done | F37: App | I37: 46325
A38: F-037 | B38: Workbench | C38: Explorer Cut / Copy / Paste of files | D38: Partial | E38: Medium | F38: Tests | G38: Unit-tested; not tried by mouse | I38: 46325
A39: F-038 | B39: Workbench | C39: Open to the Side | D39: Done | F39: App | G39: Ctrl+Enter with the Explorer focused | I39: 46325
A40: F-039 | B40: Workbench | C40: Find in Folder | D40: Done | F40: App | I40: 46325
...

Sheet How to use
B2: How to use this tracker
B4: Add a feature | C4: Go to the Features sheet, type in the first empty row under the table (it grows by itself). Give it the next ID (F-097...). Dropdowns appear for Status, Priority and Verified.
B5: Finish a feature | C5: Change Status to Done, set Verified (App = tried in the running editor), and update the Updated date.
B6: Find what is left | C6: Use the filter arrows on the Features header: Status = Partial or Not started, then sort by Priority.
B7: Dashboard | C7: Counts and percentages are formulas over the Features sheet (rows 2 to 500). A new Area needs a new row on the Dashboard: copy an area row and change its name.
B8: Status | C8: Done = built and working. Partial = built with a known gap (see Notes). Not started = not built.
B9: Priority | C9: High / Medium / Low. Filled in for open items only; the values were set by Claude and are yours to change.
B10: Verified | C10: App = checked in the running editor. Tests = unit tests only. Not verified = builds, never run.
B11: Owner / Updated | C11: Free text and a date. Left blank for you to use.
B13: Example row | C13: F-097 | Editing | Bracket pair colorization | Not started | Low | (blank) | Needs tree-sitter bracket queries | (blank) | 2026-11-02
